Workbook

Sheet Sheet1
A1: Unnamed: 0.1 | B1: Column 1 | C1: EDIH Title | D1: Description (indexed field) | E1: Country | F1: Contact name | G1: Contact Location | H1: EDIH/SoE | I1: Website | J1: Formatted sectors | K1: Formatted services | L1: Formatted technologies | M1: Unnamed: 0
A2: 1 | B2: 5 | C2: EDIH for DATA-BASED INNOVATION FOR CIRCULAR ECONOMY, OPERATIONS & SUSTAINABILITY | D2: The regional Data2Sustain EDIH consortium is a unique partnership approach across the NUTS II Northern and Western region. The consortium combines the core competences of the higher education institutes (HEI), with the innovation and business acumen of the complementary EDIH partners. This unique partnership structure demonstrates a shared management approach between researchers, technology providers, policy makers, innovation practitioners and business support agencies. The partnership structure encompasses 4 Technological Competence Centres, 3 Business support organisations, with 4 of the partners havin a local, or regional, planning, economic development, and investment remit, as well as European networked partner with extensive experience in digital innovation in public organisations. Data2Sustain is a coordinated group of organisations with complementary expertise, with a not-for-profit objective. It will support SMEs, as well as the public sector. It has a focus on circular economy, operations & sustainability areas, utilising AI, HPC and Cybersecurity technological competence, with particular emphasis of data/data analytics driven innovation and regard to energy consumption and low carbon emissions. We have jointly developed a comprehensive service programme to increase the transformation capacity and speed of SMEs/POs in the region, nationally and in Europe with regard to advanced digital innovations and skills development. The partnership has a comprehensive physical presence across the most economically challenged region of the state, with a well-established record of successfully engaging with target groups. Our ambition is to: ‘BE A LEADING EDIH IN THE PROVISION OF DIGITALISATION SERVICES IN THE AREA OF CIRCULAR ECONOMY, OPERATIONS & SUSTAINABILITY, BASED ON DATA AND DATA ANALYTICS DRIVEN INNOVATION APPROACHES HELPING TO CREATE SMARTER, GREENER, MORE SUSTAINABLE PROCESSES, SYSTEMS, PRODUCTS, SERVICES AND BUSINESS MODELS’ | E2: Ireland | F2: Mike Conroy | G2: ATU Sligo, Sligo, Co. Sligo, F91YW50, Ireland | H2: Seal of Excellence | I2: http://data2sustain.ie | J2: food and beverages, telecommunications, manufacturing and processing, construction assembly, travel and tourism, smart city, cultural and creative economy, life sciences | K2: field trial, prototyping, circular economy, sme business development, knowledge transfer, regional development, sme business development, ecosystem building | L2: artificial intelligence decision support, big data, high performance computing, cyberphysical systems, locationbased applications, communication network
A3: 2 | B3: 6 | C3: InnovTourism DIH - Gateway for Tourism innovation & digitalization, strengthening the sector ecosystem and enabling technology adoption in the industry | D3: InnovTourism DIH was designed to act as a key reference within the Portuguese and European digital innovation ecosystem, supporting SMEs, Start-ups, and PA in the sector to strive for their digital transformation processes, thus directly contributing to the Digital Europe Programme strategy of bringing digital technology to businesses, citizens and public administration. The HUB consists of a not-for-profit one-stop shop offering strategic services and tools aimed at increasing organizations digitalization, sustainability, competitiveness, production, and commercialization of products or services. A tourism industry-dedicated innovation HUB in Portugal is the ideal opportunity to generate regional, national, and European-level digital solutions through technological experimentation, finance and business advising, training, and skills development, supporting organizations developing inexistent solutions, in full alignment with the European Digital Innovation HUB spirit.The HUB action will strategically cover specific technological domains like Artificial Intelligence (AI), IoT, Biometrics, Virtual Assistants, Medium and Advances Digital skills, Gamification, AR/VR, Cloud Computing, Data Analytics, Predictable Modelling, Geolocation, Blockchain, and Cybersecurity. These topics will stand as a reference within the HUB services InnovTourism DIH is a non-profit, public-private cooperation between ten entities, coordinated by NEST Tourism Innovation Center Portugal (Cluster), followed by UniNova (Technology Interface Center), IPLeiria - Instituto Politécnico de Leiria (Entrepreneurship Knowledge Center), Algarve STP (Technology Developer), Beta-i (Accelerator), Turismo de Portugal (Tourism National Promoter), ACIFCCIM - Associação Industrial e Comercial do Funchal & Camara de Comércio e Indústria da Madeira, TTC "The Tomorrow Company" (Technology Developers), FI Group and Deloitte (Consultants). | E3: Portugal | F3: Manuel Trindade | G3: Praça do Municipio, 6200-000 Covihã, Portugal | H3: Seal of Excellence | J3: food and beverages, smart city, travel and tourism, transport mobility | K3: circular economy, ecosystem building, innovation management, knowledge transfer, sme business development, sme support, technology transfer, technological innovation, vocational training | L3: artificial intelligence decision support, big data, blockchain and distributed ledger technology dlt, cloud services, communication network, cybersecurity, digital twins, internet of things, internet services applications, virtual reality
A4: 3 | B4: 7 | C4: ANDALUSIAN DIGITAL INNOVATION HUB IN ARTIFICIAL INTELLIGENCE AND ROBOTICS | D4: The main objective of AIR-Andalusia is to set up and guarantee the correct operativity of a regional node for the European Digital Innovation Hubs in Andalusia (Spain). Located in the south of the Iberian Peninsula, Andalusia is the most populated Autonomous Community and the second largest in Spain; being an outermost region of Europe. AIR-Andalusia is conceived as a supporting tool to foster the digital transformation of the region, focused on applied Artificial Intelligence and Robotics for (a) SMEs and small mid-caps and (b) public sector organisation, as varied a sectoral coverage as possible. AIRA aims to improve entities’ efficiency and competitiveness, providing them with access to different digitalization services focused on improving business processes, products or services. The services list includes different offers of support covering the whole life cycle of the new product/service development, either to solve technical gaps (‘Test before Invest’ and ‘Training’), to foster synergies with other relevant stakeholders for the service/product development (‘Ecosystem’); options to fund potential R&D or investment projects as the last step for the scale-up of the tested solutions (‘Find Investment’). Therefore, the consortium expects to cover all the potential needs of the entities, prioritising SMEs, to help them reach market. Up to 1.624 complete services are expected to be given during the 3 years period to about 325 entities, including SMEs, start-ups and mid-caps, and public entities. Finally, mobilising new investment in the region to reach the digital transformation. The consortium (20 beneficiaries and 4 Affiliated Entities) is multisectoral and wide enough to cover the great diversity of application sectors of AI and robotics, and the territorial distribution in this extensive region, including representation of Research and Technology entities, Technological companies, Technological Parks and Entrepreneurial associations. | E4: Spain | F4: Enrique Herrera Viedma | G4: Cuesta del hospicio sn, 18071 Granada Granada, Spain | H4: Seal of Excellence | I4: https://www.airandalusia.es/es/home-espanol/ | J4: defence, education, energy, environment, health care, manufacturing and processing, personal services, public administration, security, smart city, telecommunications, transport mobility | K4: innovation management, knowledge transfer, prototyping, technological innovation, sme support, vocational training, technology transfer | L4: artificial intelligence decision support, robotics, big data, digital twins, quantum technologies computingcommunication, simulation engineering and modelling
A5: =A4+1 -> 4 | B5: 8 | C5: NASK – National Research Institute | D5: Cybersecurity and user protection – our key activities involve ensuring security online. Responding to network security violations occurring in Poland and coordinating corrective actions is the responsibility of the Centre for Cybersecurity. The Center for Standardization and Certification of NASK-PIB, an organizational unit included in the internal Organizational Regulations within NASK acts as an accredited Certification Body. The center certifies products in the field of IT security (cybersecurity). With the enactment of the Act on the national cybersecurity systems, NASK was given the important role of serving as one of three nation-wide CSIRTs. The NASK CSIRT receives and analyses reports, takes actions and coordinates responses to incidents occurring in Polish civilian cyberspace reported by key service operators, digital service providers, local authorities and individuals. It also responds to incidents involving the uploading of content which is illegal or poses a hazard to children; as well as monitoring online threats and the level of cybersecurity in individual sectors and the entire country. Keywords: Cybersecurity, Certification | E5: Poland | F5: Magda Druzd | G5: Kolska 12 st, 01-045 Warsaw, Poland | H5: DIH | I5: https://en.nask.pl/ | J5: defence, telecommunications, security | K5: knowledge transfer, regional development, sme support | L5: cloud services, cyberphysical systems, cybersecurity, internet of things
A6: =A5+1 -> 5 | B6: 9 | C6: Pôle SCS | D6: SCS (Secured Communicating Solutions) cluster (www.pole-scs.org), is based in the Provence-Alpes-Côte d’Azur region, in France, and gathers 300 members, including companies (and 70% of SMEs), research centres and educational institutions in the fields of microelectronics, IoT, Big Data, Artificial Intelligence and Digital Security. As a non-profit organisation with the status of "French Competitiveness cluster" recognised at national level, the aim of SCS cluster is to promote the development of competitive R&D projects between all these players with the support of local communities, in order to design and develop new solutions targeting high-growth markets such as smart cities, smart homes and smart buildings, smart grids, Industry x.0, or e-health. It also aims to contribute to the creation of an appropriate ecosystem for the overall regional digital and deeptech landscape, especially through the development of SMEs. The cluster represents 60 000 jobs in these fields, 26 multinational companies, 1200 researchers in the public sector and 18 educational institutions training 1500 engineers per year. Partner in the European Digital Innovation Hub Move2Digital Keywords: Open innovation, networking, Deeptech, digital technologies, IoT, AI, cybersecurity, microelectronics, electronics, optics, photonics | E6: France | F6: Marielle Campanella | G6: Place borde, 13790 Rousset, France | H6: DIH | I6: https://www.pole-scs.org/ | J6: defence, energy, health care, telecommunications, security, smart city, transport mobility | K6: innovation management, knowledge transfer, prototyping, regional development, smart specialisation strategies, sme business development, sme support, technological innovation | L6: artificial intelligence decision support, big data, cybersecurity, internet of things, micro and nanoelectronics, optoelectronics, photonics, semiconductors and nanotechnology, sensors vision processing systems, simulation engineering and modelling
A7: =A6+1 -> 6 | B7: 10 | C7: Cybersecurity Innovation Hub | D7: CIH will significantly support digital transformation and application of innovation in SMEs and public administration by building a coordinated and effective ecosystem comprising top research institutions with the necessary know-how and infrastructure, specialized business clusters, professional organizations, and public authorities. This robust ecosystem will provide its beneficiaries with access to education and information on cybersecurity trends and best practices, to expert advice and state-of-the-art infrastructures to verify the suitability and security of innovative solutions under consideration and increase the availability of funds to invest in innovation. CIH will also function as a platform for cooperation and information sharing between entities in the cybersecurity market, both at the level of Czechia and the EU. This will increase the efficiency and competitiveness of the EU cybersecurity industry, the security of IT infrastructures and the strength of the EU economy. CIH draws on partnerships and participation in international networks and builds on the success of Czech research and industry. CIH covers cybersecurity on the horizontal from various points of view (technical, legal, economic, social etc.), on the vertical CIH operates at all levels - it plays an important role in building the legislative environment, in research, commercialization and implementation of technologies, and in awareness raising and education. CIH also has links to standardization and certification that shape the cybersecurity market. This holistic approach and the ability to thoroughly map the ecosystem make CIH an attractive partner for international cooperation. This is also confirmed by its participation in 3 EU pilot research projects (Sparta, CyberSec4Europe and Concordia), cooperation with the EU and international organizations (ENISA, Europol, UN, NIST, etc.), and involvement in professional initiatives (e.g. REWIRE - capacity building in cybersecurity in the EU). | E7: Czechia | F7: Tereza Samanova | G7: Šumavská 416/15, 602 00 Brno, Czechia | H7: EDIH | I7: https://www.cybersecurityhub.cz/ | J7: defence, education, energy, environment, financial, health care, life sciences, manufacturing and processing, metal working and industrial production, personal services, public administration, retail, wholesale or distribution, security, smart city, space, telecommunications, transport mobility, transport sector, travel and tourism | K7: ecosystem building, innovation management, finance, knowledge transfer, prototyping, public sector innovation, sme business development, sme support, technological innovation, technology transfer, vocational training | L7: artificial intelligence decision support, big data, cloud services, communication network, cyberphysical systems, cybersecurity, high performance computing, internet of things, internet services applications, software architectures
A8: =A7+1 -> 7 | B8: 11 | C8: EDIH Czech Technical University in Prague | D8: The EDIH CTU represents a major European Digital Innovation Hub in the Czech Republic in the field of Artificial Intelligence (AI) and Machine Learning (ML) transferring trustworthy solutions and services to the industry, health, transportation and energy sectors. The EDIH CTU, with its vision "Inspire & Make the Czech AI-driven Industry", aims to become the innovation and technology leader in providing professional AI/ML services for the local SMEs, small mid-caps and public sector organizations with respect to their digital and green transformation. The strong consortium partners representing academia, the business sector and key associations of enterprises in the Czech Republic provide sufficient know-how, expertise and state-of-the-art experimental facilities to serve the needs of the public and private sectors at the national and also international levels. The major focus is on promoting digital transformation adoption, providing high-quality services, education and knowledge sharing, pursuing ecosystem development, and establishing strong inter-EDIH collaboration. The consortium builds upon already existing partnerships in AI and manufacturing enabling best practice sharing, expertise exchange, and joint activities seeking far-reaching synergies thus strengthening the far-reaching impacts of the European network of EDIHs. | E8: Czechia | F8: Barbora Zochova | G8: Jugoslavskych partyzanu 1580/3, 160 00 Praha, Czechia | H8: EDIH | I8: https://www.edihctu.eu | J8: telecommunications, automotive, construction assembly, education, electricity, energy, environment, health care, manufacturing and processing, metal working and industrial production, nuclear, public administration, smart city, space | K8: technology transfer, technological innovation, sme support, smart specialisation strategies, public sector innovation, circular economy, field trial, innovation management, prototyping, vocational training | L8: artificial intelligence decision support, bi tools, gamification, software architectures, sensors vision processing systems, robotics, human computer interaction, internet of things, internet services applications
A9: =A8+1 -> 8 | B9: 12 | C9: Digital Innovation Hub for a Smarter, Safer and more Sustainable Society (DIH4Society) | D9: News: launched the call for selecting the SMEs who will benefit from the services. Details & info are available: https://dih4society.ro/apel-imm/ Accelerating digital green transformation and innovation uptake across the economy and society is at the forefront of Europe’s growth agenda. Digital Innovation Hubs (DIHs) are one of the pillars to uphold this process and will help to consider the geographical (regional) dimension and thematic context to boost SME growth, citizen centered governance, jobs and investment. The COVID19 crisis has demonstrated the absolute necessity of having strong European digital ecosystems as key enablers to avoid disruption in value-chains. However, digitalization and digital transformation can only be efficient if digital ecosystems are strongly interlinked with their applied market sectors. Due to inertia and/or legacy, the manufacturing, public administration and health sectors are among the most challenging ones. The project Digital Innovation Hub for Society for a Smarter, Safer and more Sustainable Society comes to upscale the services that DIH4Society can deliver in the North-West Region of Romania and aims at fully integrating our initiative into the European network of hubs. The project focuses on two technological pillars, cybersecurity and smart robotics, while also building advanced digital competencies for digitalization and green digital transformation. Upon finalization, the project will have a profound, transformative impact on a regional level through the digital progression of 70 key stakeholders, public administration and health providers, and more than 400 SMEs from smart specialization sectors. DIH4Society will provide a European solution to a European challenge and will bring or embed digitalization in the practices of many organizations. In the long run the project will inspire a new generation of early adopters of technologies, new entrepreneurial initiatives of visionary companies and organizations that use cutting edge technologies at the core of their business models and will build the foundation for a citizen centered public service delivery. | E9: Romania | F9: Andrei KELEMEN | G9: Str. Dorobantilor 57A, First Floor, 400609 Cluj-Napoca, Romania | H9: EDIH | I9: https://dih4society.ro/ | J9: manufacturing and processing, public administration, health care, smart city, communityled local development, education, energy | K9: ecosystem building, field trial, finance, innovation management, knowledge transfer, prototyping, public sector innovation, regional development, smart specialisation strategies, sme business development, sme support, technological innovation, technology transfer, vocational training | L9: cybersecurity, robotics, artificial intelligence decision support
A10: =A9+1 -> 9 | B10: 13 | C10: Digital Innovation Hub of the Galician Industry | D10: Galicia is the 6º Spanish region least digitalized, according to the DiGiX that assesses the factors that enable to fully leverage ICTs for increased competitiveness and well-being. Being 99,92% of Galician companies SMEs, there is a clear need to address digitalization at this scale. Furthermore, manufacture is not only a critical sector for the Digital Europe Programme, but it also represents almost 15% of the Galician economy. European digitalization of SMEs goes necessarily through the digitalization of the Galicia manufacturing SMEs. DIHGIGAL's goal is to boost the digital transformation of all industry focusing on SMEs and mid-caps needs. This will be achieved by the diverse composition of its consortium: *3 leading manufacturing sectors (automotive, naval and food) represented by their clusters (CEAGA, ACLUNAGA & CLUSAGA) bringing together not only their companies (20,000M€ turnover and 50,000 employees) but also their technology centres along with a cross-sectorial ecosystem (Galicia Digital) which opens the EDIH to whole industrial sector. *4 leading competence centres combining the best capacities in HPC and AI represented by CESGA-Supercomputing Centre, ITG and Universities of Vigo and Coruña (which chairs the Spanish Association for AI) along with the private supply through the ICT cluster. *3 complementary agents (FEUGA, KPMG & Inovalabs) to provide service to the entire digital ecosystem. All of them are crucial to implement specialized actions and to extend the scope and impact of the project. In this sense, DIHGIGAL is part of a broader vision aligned with policies at regional (RIS3), national, and European (2030 Digital Compass, Green Deal, and White Paper on AI) level. In terms of the foreseeable impact, over 800 SMEs, mid-caps and public entities are expected to benefit directly from the project and the collaboration with other EDIHs. This is DIHGIGAL commitment to enhance the twin transition in Galicia and, hence, the EU. | E10: Spain | F10: Josefina Alonso Nocelo | G10: Avda. Citroën, 3 y 5 – Edificio Zona Franca 1ª Planta, 36210 Vigo Pontevedra, Spain | H10: Seal of Excellence | I10: https://dihgigal.com | J10: manufacturing and processing, automotive, transport mobility, food and beverages, maritime, retail, wholesale or distribution, textiles | K10: sme support, ecosystem building, finance, technological innovation, circular economy, innovation management, vocational training, technology transfer, smart specialisation strategies, regional development, public sector innovation | L10: artificial intelligence decision support, high performance computing, big data, cybersecurity, internet of things, mobility, quantum technologies computingcommunication, sensors vision processing systems
A11: =A10+1 -> 10 | B11: 14 | C11: Digital Innovation Hub for Nouvelle-Aquitaine Manufacturing Industry Community | D11: Led by a consortium of 13 partners, DIHNAMIC aims to give access to AI-based digital technologies, advanced robotics, digital twinning and intelligent systems. Granting access to these resources is expected to accelerate and guide the green, digital and sustainable transition of 116 innovative manufacturing companies and 8 public authorities from the French Nouvelle-Aquitaine region. With a total number of 600 services delivered over the course 3 years, DIHNAMIC will encourage and support the development of a digitised, resilient and resource-efficient industry in line with trustworthy AI concepts. DIHNAMIC will contribute to the objectives laid-out in policies such as the New Industrial Strategy for Europe, the Digital Europe Programme”, "Europe fit for the Digital Age Strategy”, or the “European Green Deal”. The services offered are designed to foster the uptake of trustworthy AI, in response to the industry's need to adapt to current economic, ecological and societal challenges, while considering applied ethical and environmental aspects in their innovation and digitalisation process. AI-based service follow the recommendations from the “European Trustworthy AI strategy” Links and partnerships will be established with other EDIHs and research centres active in AI, HPC and Cybersecurity. DIHNAMIC will act as a transmission belt, transmitting feedbacks from the regional ecosystem to European authorities while contributing to the implementation of European policies and strategies. DIHNAMIC will also facilitate the access of regional companies to finance, helping companies to raise a total of 2 million euros in additional investment over the course of 3 years. To enable a rapid start of the project, DIHNAMIC has already established a customer journey and developed dedicated delivery channels to favour cross-learning and impactful service delivery. | E11: France | F11: Véronique Desbleds | G11: 6 allee du doyen georges brus, 33600 Pessac, France | H11: EDIH | I11: https://www.dihnamic.eu | J11: manufacturing and processing, aeronautics, agricultural biotechnology and food biotechnology, health care, energy, defence, environment, transport sector | K11: technological innovation, prototyping, public sector innovation, ecosystem building, sme support | L11: artificial intelligence decision support, big data, digital twins, high performance computing, human computer interaction, internet of things, robotics, virtual reality, additive manufacturing, cybersecurity, logistics
A12: =A11+1 -> 11 | B12: 15 | C12: EDIH CASSOVIUM | D12: Mission of the project EDIH CASSOVIUM (EDCASS) is to support reinforcement of European critical digital technologies and their best use in green digital transformation of industrial and public ecosystems in the region of the Eastern Slovakia Region (ESK-REG). Consortium of three top-research and innovation institutions in ESK-REG – two internationally recognised universities Technical University in Košice (coordinator) and Pavol Jozef Šafárik University in Košice, and a highly recognised ICT cluster Košice IT Valley. ESK-REG consisting of Košice Self-governing Region and Prešov Self-governing Region, which in European context are classified as “less developing regions” has low level of innovation score and use of digital services, also low an unemployment rate (of 8.2 %) and level of average wages. Therefore, it is important that EDCASS ensures its digital transformation services are easily accessible to all SMEs (95+ % of all companies in ESK-REG) and public institutions. The key goal of EDCASS is to provide one-stop-shop support for four categories of EDIH services with an adequate, knowledge-based, and technically high-quality range of information technologies guaranteed by the ecosystem of the consortium partners. The consortium covers a wide range of multi-sectors and multi-dimensional ICT areas, which fall within research and educational competencies of all partners. EDCASS platform is based on three basic pillars: 1) Artificial Intelligence and Robotics; 2) Industry 4.0/5.0 concepts, application and implementation; 3) Cyber security solutions for commercial and public subjects. In line with its mission, these services and technologies are and will be supported by active links to European DIH, EDIH networks and other European networks (EEN, Startup Europe) and bilateral collaboration with suitable partner research and innovation institutions. | E12: Slovakia | F12: Miroslav Michalko | G12: Letná 1/9, 042 00 Košice, Slovakia | H12: EDIH | I12: https://www.edihcassovium.sk | J12: manufacturing and processing, smart city, public administration, energy, transport mobility, telecommunications, education, aeronautics, construction assembly, cultural and creative economy, metal working and industrial production, travel and tourism, mining and extraction | K12: prototyping, innovation management, ecosystem building, sme business development, technology transfer, technological innovation, public sector innovation, regional development, smart specialisation strategies, vocational training, finance, circular economy | L12: artificial intelligence decision support, cybersecurity, robotics, big data, simulation engineering and modelling, software architectures, internet of things, cyberphysical systems, cloud services, communication network, additive manufacturing, digital twins, virtual reality, blockchain and distributed ledger technology dlt, micro and nanoelectronics, optoelectronics, gamification, high performance computing
A13: =A12+1 -> 12 | B13: 16 | C13: EDIH Lombardia | D13: EDIH L - M.I.A. Lombardia The mission of EDIH Lombardia (EDIH L) is to lead and implement the digital and sustainable twin transition of Lombardy’s manufacturing industry through a comprehensive portfolio of services provided by its partners. Recognized as a EDIH and awarded the "Seal of Excellence", EDIH Lombardia plays a key role in driving digital and sustainable transformation in Lombardy, one of Europe’s most productive regions. Recently renamed as Manufacturing Innovation Alliance (M.I.A.) Lombardia, the organization is a consortium of 12 partners dedicated to supporting manufacturing companies in their digitalization efforts, in alignment with European and national industrial policies. The consortium includes 1 Competence Center, 1 Digital Innovation Hub (both listed in the JRC catalogue), 4 Technology Clusters, 3 Business Associations, 1 Financial Institution, 2 EIT Nodes. M.I.A. Lombardia aims to support digitalization and sustainability in the manufacturing sector, with a particular focus on SMEs. It offers a broad range of tailored services, including consultancy, training, and access to funding, helping companies adopt innovative technologies, enhance competitiveness, and drive sustainable transformation. Specific Objectives Supporting digital and sustainable transformation:M.I.A. Lombardia guides manufacturing companies through their digitalization journey, promoting the adoption of advanced technologies to improve efficiency and sustainability. This includes Industry 4.0 solutions and greener, more digitalized processes. Providing personalized services:The hub offers tailored services such as technical consultancy, training, and audits, adapting to each company's specific needs. This approach enables businesses to tackle digitalization challenges with the right tools and scalable solutions based on their digital maturity level. Leveraging NRRP funds and state incentives:Through PNRR financing and various incentives, M.I.A. Lombardia provides companies with financial resources to support the adoption of innovative technologies. These funds are allocated based on company size, with some incentives covering up to 100% of costs for micro and small enterprises. Promoting advanced technological skills:M.I.A. Lombardia organizes awareness-raising and training initiatives to help companies understand and implement new technologies. By offering testing programs and prototype development, businesses can evaluate technological solutions before large-scale investments, reducing risks and accelerating digital transformation. As part of M.I.A. Lombardia, MADE coordinates the “EDIH Manufacturing Network – EDIH4MANU”, an open, informal collaboration network of 25 EDIH candidates from 15 EU countries. This network aims to connect Europe’s most advanced manufacturing regions, share specializations, best practices, competencies, and services, and promote the digital transition of European industry. | E13: Italy | F13: Carlo Ongini | G13: Piazza Leonardo Da Vinci 32, 20133 Milano MI, Italy | H13: Seal of Excellence | I13: https://www.mialombardia.it/ | J13: manufacturing and processing, communityled local development, life sciences, textiles, aeronautics, education, metal working and industrial production, automotive | K13: sme support, technology transfer, vocational training, field trial, prototyping, regional development, ecosystem building, innovation management, circular economy, technological innovation | L13: artificial intelligence decision support, human computer interaction, robotics, digital twins, cybersecurity, big data, additive manufacturing, internet of things, logistics, simulation engineering and modelling, virtual reality
A14: =A13+1 -> 13 | B14: 17 | C14: EDIH MADRID REGION | D14: Madrid is a Spanish region covering only 1.6% (8,030 km2) of the country’s area but it generates 19,3% of Gross Domestic Product (GDP) and where 14,2% (6.7 million) of the population of the Country live. Madrid Region has one of the major enterprise’s densities of all country, 85.8 companies per 1,000 inhabitants and it concentrates near 16,2% of all companies in Spain. In total, there are 552,027 enterprises in the Region . This makes Madrid Region a Business decision Centre. The EDIH MADRID REGION is created with the aim of being the reference Centre to improve the digitization of both public sector and small and medium-sized companies in Madrid Region. To achieve this ambitious goal, EDIH MADRID REGION is made up of a powerful consortium of 11 partners. EDIH MADRID REGION is led (coordinated) and co-financed by the regional government of Madrid. One of the members of the consortium is the Fundación para el Conocimiento madri+d (Fmi+d), which is the coordinator of the Madrid node of the European Enterprise Network (EEN). In this way, it is ensured that EDIH MADRID REGION will offer a continuous service with EEN and Startup Europe. Among the EDIH MADRID REGION partners there are several partners who have a deep understanding of the needs of the entities to which the services to be provided by the EDIH are addressed. EDIH MADRID REGION partners include several partners with extensive experience in developing solutions based on the key digital technologies of the Digital Europe programme. Based on the key sectors identified in the previous strategy, the regional policies in various areas, the priorities of the Digital Europe program and the experience of the partners of the EDIH MADRID REGION consortium, it has been decided to prioritize the following economic sectors to give their digitization support services: o SMEs in the services sector o SMEs in the industrial sector: Industry 4.0 o Regional and municipal public administration o The area of mobility | E14: Spain | F14: Pedro Jesus Rodriguez | G14: Calle del Maestro Ángel Llorca, 6, 28003 Madrid Madrid, Spain | H14: EDIH | J14: manufacturing and processing, personal services, public administration, education, transport mobility, construction assembly, aeronautics, agricultural biotechnology and food biotechnology, transport sector, travel and tourism | K14: knowledge transfer, innovation management, prototyping, public sector innovation, sme support, technological innovation, technology transfer | L14: artificial intelligence decision support, cybersecurity, high performance computing, blockchain and distributed ledger technology dlt, robotics, simulation engineering and modelling, mobility, cloud services, locationbased applications, internet of things
A15: =A14+1 -> 14 | B15: 18 | C15: European Digital Innovation Hub for employee-centered digital transformation in South Westphalia | D15: The planned EDIH is located in the German region of South Westphalia. South Westphalia is an industrial region with a strong focus on small and medium-sized enterprises (SMEs), with more than 150 so-called “hidden champions”, i.e. those often little-known small and medium-sized enterprises that are among the European and world market leaders in niche markets. The major industrial sectors of metal production and processing as well as mechanical engineering generate 75 % of total sales in the industrial sector each year, accounting for about two-thirds of total industrial employment. South Westphalia is therefore not only the third strongest region in Germany and by far the strongest industrial region in North Rhine-Westphalia (most populous federal state in Germany), but also one of the oldest industrial regions in Europe. However, the strategic orientation of EU policies and the twin objectives of making Europe greener and more digital poses challenges for the rather traditional “old industry” within South Westphalia. The focus must therefore be on providing the best possible support for SMEs within South Westphalia in overcoming these challenges. For this reason, establishing an EDIH with a strong European orientation is of particular benefit to the South Westphalian economy with its high export quota. The economic success of SMEs in South Westphalia is based on the expertise of their employees, which has grown over decades. The EDIH SWF will provide a set of services and infrastructures to support SMEs in how this product-specific expertise of human specialists and executives can be complemented by the adoption and development of in-depth, socio-informatic digitization competencies in the design of human-centered artificial intelligence, employee-based cyber-security as well as socio-technical assistance systems. The EDIH will support SMEs during the transformation process in cooperation with the social partners to maintain innovative strength in the long term. | E15: Germany | F15: Thomas Ludwig | G15: Adolf-Reichwein-Strasse 2a, 57076 Siegen, Germany | H15: EDIH | J15: manufacturing and processing, metal working and industrial production, automotive, construction assembly, public administration, smart city, health care | K15: prototyping, sme support, field trial, innovation management, knowledge transfer, circular economy, technological innovation, technology transfer, public sector innovation | L15: cyberphysical systems, human computer interaction, additive manufacturing, internet of things, digital twins, virtual reality, artificial intelligence decision support, gamification, internet services applications, laserbased manufacturing and materials processing, robotics, new technologies for audiovisual sector media, cybersecurity, mobility
A16: =A15+1 -> 15 | B16: 19 | C16: EDIH VILNIUS: accelerating green and digital transformation in Vilnius region | D16: Responding to the DIGITAL-2021-EDIH-01-INITIAL call, EDIH VILNIUS is submitting the proposal with a goal to enable the EDIH VILNIUS to effectively support the digital and green transformation of SMEs and public sector organisations in the Vilnius region. The specific objectives of the project directly correspond to the objectives of the call and are the following:(1) to ensure full integration of the EDIH VILNIUS into a common network of EDIHs in order to facilitate effective international cooperation and service provision as well as identify and cover the needs of Vilnius region SMEs and public sector organisations in a field of digital and green transformation by providing a full package of integrated services(2) to upgrade the capacity of the EDIH VILNIUS to ensure the proper provision of these services(3) to build networks between EDIH VILNIUS and other relevant organisations in Europe and worldwide in order to ensure sharing of capacities and knowledge, especially, in the fields of High Performance Computing, Artificial Intelligence, Cybersecurity, Advanced Digital Skills. Moreover, the project will directly contribute to the overall Digital Europe Programme objectives as EDIH VILNIUS will become a part of EDIHs network on the EU level and will help to cover a specific EU region (Vilnius region, Lithuania). EDIH VILNIUS is already a mature consortium which is deeply engaged in its activities. At the moment the consortium brings together digital technology expertise, with the specific focus on AI technologies, in different sectors as well as infrastructure needed to provide high quality services in the Vilnius region. Therefore, EDIH VILNIUS is able to ensure a successful implementation of the project and its objectives. The project will help members of EDIH VILNIUS to better combine their forces, infrastructure and competencies for a common goal - comprehensive digital and green transformation of Lithuanian industry, SMEs and public sector organisations. | E16: Lithuania | F16: Evelina Šalavėjienė | G16: Sauletekio al. 15, 10224 Vilnius Lithuania, Lithuania | H16: EDIH | I16: http://www.edih.lt | J16: manufacturing and processing, manufacturing and processing, education | K16: circular economy, sme support, technological innovation, technology transfer, sme business development, ecosystem building | L16: additive manufacturing, artificial intelligence decision support, cyberphysical systems, cybersecurity, digital twins, high performance computing, internet of things
A17: =A16+1 -> 16 | B17: 20 | C17: EDIH-DIGIMAT: Flexible Manufacturing Systems Using Artificial Intelligence | D17: EDIH-DIGIMAT’s vision is more digitalized, productive, and competitive manufacturing sector, with its workforce adapted to this trend. It wants to contribute to sustaining the importance of the manufacturing sector to the Czech GDP, employment level, and exports. To achieve its objectives, EDIH-DIGIMAT proposes a comprehensive, structured program for digitalization of manufacturing companies, starting by raising the awareness, continued education of the companies’ staff, providing advisory and consultancy services to the respective company management levels, through experimenting with the companies at the test rigs. EDIH-DIGIMAT’s consortium builds on a successful first operational DIH in the country – DIGIMAT. It consists of four partners: INTEMAC as a lead partner with its footprint in digital consultancy services, JIC with funding services and business consulting in general, Effectivity serving the industry on their productivity growth journey, and BUT as the largest technology university in the country with a wide spectrum of technical expertise and a wide network of industry partners. To elevate the services offered, the EDIH-DIGIMAT engaged multiple clusters and partner organizations, both domestically and abroad. The array of partners includes also technology providers, domestic as well as foreign EDIH candidates. This approach has been designed to ensure relevance of provided services in time, as well as to increase the depth and breadth of provided services. The EDIH-DIGIMAT is going to be backed by a robust governance model to ensure the proposed plan is going to be executed for the benefit of the targeted manufacturing sector, and the society at large. | E17: Czechia | F17: Veronika Vecerova | G17: Blanenska 1288/27, 664 34 Kurim, Czechia | H17: EDIH | I17: https://www.edih-digimat.cz/ | J17: manufacturing and processing, automotive, construction assembly, energy, environment, metal working and industrial production, polymers and plastics | K17: circular economy, ecosystem building, innovation management, knowledge transfer, prototyping, sme support, technological innovation, technology transfer, vocational training | L17: additive manufacturing, artificial intelligence decision support, digital twins, internet of things, cyberphysical systems, robotics, sensors vision processing systems
A18: =A17+1 -> 17 | B18: 21 | C18: Digital Hub Logistics Dortmund as European Digital Innovation Hub | D18: The aim of the Digital Hub Logistics Dortmund as EDIHDO is to increase the dissemination, acceptance and adoption of digital technologies and their successful application for the development of product, process and business model innovations by SMEs. To this end, EDIHDO offers support formats and services in the categories Test before Invest, Skills & Training, Investment Search Support and Innovation Ecosystem & Networking. EDIHDO is supported by Fraunhofer IML and TU Dortmund as competence centres, Digital Hub Management as orchestrator and finally TZNet, a subsidiary of the City of Dortmund, and WFG Kreis Unna, a subsidiary of the district of Unna, as multipliers. EDIHDO focuses on the application area of logistics, manufacturing and production. In the area of digitalisation, the technological focal points include artificial intelligence, high-performance computing, the Internet of Things, blockchain, sovereign data exchange and cyber-physical systems, based on the needs of companies in the region, the potential in the application area and the competences of the consortium partners. Since the successful use of digital technologies in innovative products, processes and business models requires above all the digital competences of the employees, EDIHDO also places a special focus on offers in the area of digital further qualification. In the area of cyber security, which also plays an important role in the acceptance and implementation of digital technologies, EDIHDO acts as an intermediary to the existing competence centres in the region. Further technology competences can be brought in through cross-border cooperation and exchange in the EDIH network. In this way, SMEs and SMEs in the region can be comprehensively supported in the digital transformation, the strengthening of competitiveness can be ensured and thus the regional economic competitiveness and future viability can be secured. | E18: Germany | F18: Maria Beck | G18: Emil-Figge-Straße 80, 44227 Dortmund, Germany | H18: EDIH | I18: https://edih-do.eu/en/ | J18: manufacturing and processing, metal working and industrial production, automotive, transport mobility, communityled local development, smart city, real estate, retail, wholesale or distribution, cultural and creative economy, personal services | K18: sme support, ecosystem building, innovation management, knowledge transfer, regional development, prototyping, vocational training, sme business development, technological innovation, technology transfer, field trial, finance, circular economy, smart specialisation strategies | L18: logistics, artificial intelligence decision support, big data, digital twins, internet of things, additive manufacturing, cyberphysical systems, robotics, blockchain and distributed ledger technology dlt, cloud services, cybersecurity, gamification
A19: =A18+1 -> 18 | B19: 22 | C19: Development of AI – ICT for Manufacturing EDIH in Latvia | D19: LDIH unites Latvia’s leading research and technology organizations that are well-positioned to deliver technological and expert services. Based on a field of specialization, key enabling technologies under this category are AI and robotic solutions for manufacturing and business process automation. An Applied AI Knowledge Centre will be established to create an environment for detailed internal and external business process research. The purpose of the AI Centre Lab will be to demonstrate and model for businesses the advantages of implementing AI solutions in production processes tailored to their business model. In terms of community impact, the centre aims to increase accessibility to digital guidance and infrastructure in a local perspective, making it a matchmaking platform for scientists and businesses. The centre will provide the virtual and physical infrastructure for events and content creation. On a larger scale, the foundation of the centre will serve as an entity that holds knowledge and executes national-level digital transformation. Furthermore, it will connect the local digital ecosystem to the European digital network community and tap into the global AI community. LDIH will facilitate awareness in municipalities of the benefits of digitalisation in sustainable development and work towards an improved business environment in regions. This will be achieved by sharing best practice cases on implementing measures to facilitate the uptake of digital technologies, consequently improving the business environment and providing training and courses for Latvian municipality employees to raise awareness regarding the opportunities and impact that digitalisation can bring to local communities as well as skills improvement to mainstream the use of e-governance tools. | E19: Latvia | F19: Ilze Raudina | G19: Skolas iela 11, Riga, LV-1010, Latvia | H19: EDIH | I19: https://dih.lv/lv | J19: manufacturing and processing, transport mobility, smart city, metal working and industrial production, food and beverages, energy, education, automotive, agricultural biotechnology and food biotechnology | K19: ecosystem building, regional development, sme business development, sme support, technological innovation, technology transfer, smart specialisation strategies | L19: artificial intelligence decision support, big data, cloud services, communication network, cybersecurity, digital twins, high performance computing, internet of things, internet services applications, mobility, quantum technologies computingcommunication, robotics, sensors vision processing systems, virtual reality
A20: =A19+1 -> 19 | B20: 23 | C20: EDIH Odense for deployment of collaborative robots (cobots) in many domains especially manufacturing and logistics | D20: Aim: The purpose of EDOcobot is to improve robot skills and increase the deployment of useful collaborative robots (cobots) in SMEs and small mid-caps and thereby support production in Denmark and Europe, supporting DIGITAL objectives. Method: We categorised end users according to their robot experience and general digital skills and have designed a set of services that cover the whole continuum. As experienced companies are already aware of many options and opportunities, our services focus particularly on beginner SMEs. Beginners are introduced to the variety of cobot systems and led to discover which would work best for them, how their factory needs to be reorganised for the cobot, and how this investment can be funded. “Robot-ready” SMEs are encouraged to deploy more cobots, also in other types of application, and to train more of their staff to operate and program cobots. “Innovator” SMEs are taught how to optimize the way they use cobots and are introduced to tech suppliers, while “Front-runners” are matched with tech developers (and perhaps research calls) so that their end-user challenge can contribute to the future direction of the tech. Expected results: All our customers develop a deeper understanding of cobots and how to use them to best advantage, increasing their hands-on digital skills. They also gain better knowledge of funding opportunities and interact with the wider robot ecosystem. More cobots are deployed in various industrial sectors, including those where robot penetration is traditionally low. Mitigation of the shortage of skilled labour, reduction in workplace injuries, more reliable product quality, less waste. Relevance to the call: Increasing the robot awareness and skills of “beginners” will have great impact on the overall digital skills of European SMEs. Improving European productivity will reduce our reliance on foreign supply chains. Cobots are an accelerating market, so the EDIH network needs a node with a pure cobot focus. | E20: Denmark | F20: Lars Kristensen | G20: Munkebjergvænget 1, 5230 Odense M, Denmark | H20: EDIH | J20: manufacturing and processing, public administration, metal working and industrial production | K20: innovation management, knowledge transfer, prototyping, sme support, technological innovation | L20: robotics, logistics, artificial intelligence decision support, mobility, sensors vision processing systems
A21: =A20+1 -> 20 | B21: 24 | C21: Flanders Artificial Intelligence European Digital Innovation Hub | D21: Given the technology potential of AI, there is an urgency to accelerate the adoption of AI by SMEs and other organisations. The Flanders AI EDIH intents to accelerate the adoption of AI among by an integrated service offering: (1.) Test before invest: initial advice, individual coaching, AI technical feasibility study, legal workshops and our special co-operation with commercial AI agencies, called "Start AI" (2.) Skills and training: inspiration sessions, thematic webinars & events, masterclasses and summer schools (3.) Innovation ecosystem and networking: talent & skills matchmaking, matchmaking on AI supply & demand, matchmaking on joint research and our large annual AI event called "Flanders AI Forum" (next edition: spring 2024). The Flanders AI EDIH strengthens the Flemish Industry Partnership (Industriepartnerschap), the Flanders AI Academy (VAIA) and the Knowledge Center Data & Society (Kenniscentrum Data & Maatschappij). The Flanders AI EDIH consists of complementary partners who guarantee a cross-sectoral and accessible Flemish operation, with a local physical presence in every Flemish province. Additionally, the EDIH is aligned and maintains direct links with existing innovation actors and initiatives (such as the spearhead clusters), the Flemish AI policy plan, the Flanders AI Research Program and Enterprise Europe Network (EEN) Flanders. At European level, the Flanders AI EDIH has ongoing collaborations through the AI DIH Network, the Smart Connectivity DIH Network (SCoDIHNet), the EPoSS Smart Systems EDIH Task Force, the Vanguard AI Pilot. | E21: Belgium | F21: Gilles Wuyts | G21: Kapeldreef 75, 3001 Leuven, Belgium | H21: EDIH | I21: https://flandersaihub.eu/ | J21: manufacturing and processing, transport mobility, textiles | K21: technological innovation, ecosystem building, sme support | L21: artificial intelligence decision support, big data, digital twins
A22: =A21+1 -> 21 | B22: 25 | C22: European Digital Innovation Hub Saarland | D22: EDIH Saarland is the digital innovation catalyst and integrator serving the needs of structural transformation in Saarland, the Federal State (Land) of Germany, by offering to regional SME’s, mid-caps and public sector entities a comprehensive service portfolio with the focus on Artificial Intelligence and other key enabling technologies. EDIH Saarland addresses essential regional innovation needs of green and digital transition, builds upon and makes a major contribution to the implementation of the regional innovation strategy and, at the same time, opens up its services to the entire EDIH network, thus putting the regional innovation strategy into the European context. The EDIH Saarland specialization in Industrial AI and AI for eGovernment is based on the significant and relevant testing and experimentation facilities, professional community of experts and regional innovation infrastructure. EDIH Saarland builds on existing partnership and various ongoing activities providing coordination and triggering a synergy effect. As an innovation broker, EDIH Saarland will facilitate and support the collaborative ecosystem including major research/innovation stakeholders with outstanding competences in the focus area, and local industrial and public sector organizations in need for digital transformation. The Hub’s work plan includes the set of activities aimed at making the EDIH Saarland’s service portfolio available for other EDIHs with the focus on further integration within the Greater Region and sectoral specialization (e.g. automotive industries). The EDIH Saarland consortium brings together the major regional RTD and innovation players, has established the privileged relations with the Saarland’s Government and other stakeholders, such as industrial clusters, research and education performers, business incubators etc., and, therefore, has ensured sustainable and lasting foundation for its operation. | E22: Germany | F22: Attique Bashir | G22: Eschberger Weg 46, Gewerbepark Geb. 9, 66121 Saarbrücken, Germany | H22: EDIH | I22: https://edih-saarland.de/ | J22: manufacturing and processing, automotive, retail, wholesale or distribution, metal working and industrial production | K22: sme support, technology transfer, knowledge transfer, prototyping, technological innovation | L22: artificial intelligence decision support, cyberphysical systems, human computer interaction, robotics, cybersecurity, digital twins, big data, sensors vision processing systems, simulation engineering and modelling, virtual reality
A23: =A22+1 -> 22 | B23: 26 | C23: MicroCyber | D23: The MicroCyber EDIH aims at establishing a set of services and infrastructures focusing on cybersecurity, to be offered to Micro and Small, and enterprises (MSE) in the South of Italy while also supporting public entities – both local and central – in understanding their cybersecurity needs. MSEs in the South of Italy need to improve their cybersecurity awareness and preparedness, as a key enabler for operating and thriving in the digital economy. Still, these MSEs are often unable to face the costs for accessing resources needed to improve their cyber-preparedness and are not able to find training and capacity building programs tailored to their needs and resources availability. To respond to these needs, MicroCyber offers a diversified set of services devoted to its target groups, including assessment of digital and cyber maturity and relevant needs, cyber-range activities to explore and test cybersecurity scenarios and solutions, personalised skills and training activities, networking, also via the involvement in ecosystems and events, as well as support services to access microfinance tools and other financial resources, which the MicroCyber EDIH is perfectly positioned to deliver leveraging the unique expertise of its Coordinator, Ente Nazionale per il Microcredito (ENM). At the same time, the MicroCyber can build on the unique combination of expertise available within its consortium, with public entities, universities, large SMEs associations, research consortia, private consultancy companies, all equally committed to deliver the highest quality in services, while offering networking and collaboration with the best digital expertises in Europe, via other EDIHs, the Digital Transformation Accelerator, and a variety of other networks in the digital domain available at the local and national level. | E23: Italy | F23: Giovanni Nicola Pes | G23: Via vittoria colonna 1, 00193 Roma RM, Italy | H23: EDIH | I23: https://www.microcyber.eu/2025/ | J23: manufacturing and processing, communityled local development, consumer products, financial, public administration, retail, wholesale or distribution | K23: sme support, knowledge transfer, technology transfer, technological innovation, ecosystem building | L23: cybersecurity, internet services applications
